[2023-10-10 11:04:01,962][root][ERROR] - An error occurred Error communicating with OpenAI: HTTPSConnectionPool(host='api.openai.com', port=443): Max retries exceeded with url: /v1/chat/completions (Caused by NameResolutionError("<urllib3.connection.HTTPSConnection object at 0x1599ed5d0>: Failed to resolve 'api.openai.com' ([Errno 8] nodename nor servname provided, or not known)"))
